Workbook

Sheet Instructions
G3: Instructions
B5: 1 | C5: Work on data 2 months from the current month, e.g. if in July work on May data
B6: 2 | C6: Complete DQA with the calendar month, focus on collecting before data first week of the month and after data last 2 weeks of the month
B7: 3 | C7: Ensure you give clear guidance to DoH staff on how to correct the data, once you have completed the DQA with before data
B8: 4 | C8: For DSTB outcomes, work on cohort started treatment 12 months ago, e.g if in July 2022 work on July 2021 cohort
B9: 5 | C9: For DRTB outcomes, work on cohort started treatment 24 months ago, e.g if in July 2022 work on July 2020 cohort
B10: 6 | C10: Grey cells have fomula, please do not insert any data
B11: 7 | C11: When cell color changes to red, please make sure you review data and correct it
B12: 8 | C12: Please complete the Training dashboard as per facility visit book information
B13: 9 | C13: Please ignore the Power Query tab, this is for further analysis
C15: Conversions (Work on data 2 months back for this section)
C16: These are patient that were due for conversion (started in e.g March 2023)
C18: Discharge (Work on data 2 months back, for this section the people would have started treatment 5 months back e.g 2 months back in March then go 5 months back to Oct 2022)
C20: Outstanding outcomes list (Work on data 2 months back, for this section the people would have started treatment 5 months back e.g 2 months back in March then go 5 months back to Oct 2022)
C22: HIV/ART - Need to filter from the Patient list since the report doesn’t give you patient level data only if there are any outstanding HIV/ART status.
C24: Outcome report - This is the total number 12 months back outcome
C25: You also filter since the report is not out yet.
C27: Dashboard
B28: 1 | C28: Please use the dashboard and areas highlighted in red to give DoH staff feedback
B29: 2 | C29: Be sure to commend DoH staff when doing well, refer to our documentation lessons learnt document

Sheet ICD10 codes
B1: PTB/EPTB | C1: ICD Code | D1: Definition | E1: Type Sample/Type Test
A2: Respiratory TB, nactoriolocally confirmed: A15 | B2: PTB | C2: A15.0 | D2: TB of lung, confirmed by sputum microscopy with or without culture | E2: Sputum: Smear +ve with or without culture result
B3: PTB | C3: A15.1 | D3: TB of lung, confirmed by culture only | E3: Sputum: Culture positive
B4: PTB | C4: A15.2 | D4: TB of lung, confirmed by histologically | E4: Biopsy: Histology
B5: PTB | C5: A15.3 | D5: TB of lung, confirmed by unspecified means | E5: Laboratory confirmed FIB; Xpert +ve or Xpert +ve/smear -ve and other tests
B6: EPTB | C6: A15.4 | D6: TB of intrathoracic lymph nodes, confirmed bacteriologically and histologically | E6: Biopsy: Smear/Xpert/culture/histology
B7: EPTB | C7: A15.5 | D7: Tuberculosis of the larynx, trachea and bronchus, confirmed bacteriologically and histologically | E7: Biopsy: Smear/Xpert/culture/histology
B8: EPTB | C8: A15.6 | D8: Tuberculous pleurisy, confirmed bacteriologically and histologically | E8: Biopsy: Smear/Xpert/culture/histology
B9: EPTB | C9: A15.7 | D9: Primary respiratory TB, confirmed bacteriologically and histologically | E9: Biopsy: Smear/Xpert/culture/histology
B10: EPTB | C10: A15.8 | D10: Other respiratory tuberculosis, confirmed bacteriologically or histologically | E10: Biopsy: Smear/Xpert/culture/histology
B11: EPTB | C11: A15.9 | D11: Respiratory tuberculosis unspecified, confirmed bacteriologically and histologically | E11: Biopsy: Smear/Xpert/culture/histology
A12: Respiratory TB, not bacteriologically and histologically confirmed: A16 | B12: PTB | C12: A16.0 | D12: TB of lung, bacteriological and histologically negative | E12: X-Rays/ClinicalSputum (smear/Xpert or culture) /biopsy done but negative
B13: PTB | C13: A16.1 | D13: TB of lung, bacteriological and histological examination not done | E13: X-Rays/Clinical NO sputum (smear/Xpert or culture) /biopsy tests done
B14: PTB | C14: A16.2 | D14: TB of lung, without mention of bacteriological and histological confirmation | E14: X-Rays and Clinical (no smear/Xpert or culture result)
B15: EPTB | C15: A16.3 | D15: TB of intra-thoracic lymph nodes, without mention of bacteriological or histological confirmation | E15: X-Rays/Clinical NO sputum (smear/Xpert or culture) /biopsy tests done
B16: EPTB | C16: A16.4 | D16: Tuberculosis of the larynx, trachea and bronchus, without mention of bacteriological or histological confirmation | E16: X-Rays/ClinicalNO sputum (smear/Xpert or culture)/biopsy tests done
B17: EPTB | C17: A16.5 | D17: Tuberculous pleurisy, without mention of bacteriological or histological confirmation | E17: X-Rays/Clinical NO sputum (smear/Xpert or culture)/biopsy tests done
B18: EPTB | C18: A16.7 | D18: Primary respiratory TB without mention of bacteriological or histological confirmation | E18: X-Rays/Clinical NO sputum (smear/Xpert or culture)/biopsy tests done
B19: EPTB | C19: A16.8 | D19: Other respiratory tuberculosis, without mention of bacteriological or histological confirmation | E19: X-Rays/Clinical NO sputum (smear/Xpert or culture)/biopsy tests done
B20: EPTB | C20: A16.9 | D20: Respiratory tuberculosis unspecified, without bacteriological or histological confirmation | E20: X-Rays/Clinical NO sputum (smear/Xpert or culture)/biopsy tests done
A21: Extra Pulmonary + other | B21: EPTB | C21: A17.0+ | D21: TB meningitis (G01) | E21: CSF
B22: EPTB | C22: A17.1+ | D22: Meningeal tuberculoma (G07) | E22: MRI/CAT scan
B23: EPTB | C23: A18.0 | D23: TB of bones and joints | E23: Aspiration/biopsy/Xray
B24: EPTB | C24: A18.1 | D24: TB of genitourinary system | E24: Urine culture / Biospsy
B25: EPTB | C25: A18.2 | D25: Tuberculous peripheral lymphadenopathy | E25: Aspiration/biopsy
B26: EPTB | C26: A18.3 | D26: TB of intestines, peritoneum and mesenteric glands | E26: Aspiration/biopsy/MRI/CAT scan
B27: EPTB | C27: A18.4 | D27: TB of skin and subcutaneous tissue | E27: Biopsy
B28: EPTB | C28: A18.8 | D28: TB of other specified organs | E28: Biopsy/aspiration/scan
B29: PTB | C29: A19.0 | D29: Acute miliary TB of a single specified site | E29: Blood culture / Xray / Clinical
B30: PTB | C30: A19.1 | D30: Acute miliary TB of multiple sites | E30: Blood culture / scan
B31: PTB | C31: A19.2 | D31: Acute miliary TB, unspecified | E31: Blood culture / scan
B32: EPTB | C32: P37.0 | D32: Congenital TB | E32: Blood culture / scan / other
B33: PTB | C33: J65 | D33: Silicotuberculosis | E33: PTB & confirmed silicosis
B34: PTB | C34: J65 | D34: Pneumoconiosis associated with TB | E34: PTB & confirmed pneumoconiosis

Sheet Quality assurance
A1: ='Power Query'!K2 -> Data type | C1: ='Power Query'!M2 -> Element | D1: ='Power Query'!P2 -> TIER.Net | G1: ='Power Query'!Q2 -> DHIS
B2: Age grooup | D2: Before | E2: After | F2: Validation result | G2: Before | H2: After | I2: Validation result | J2: TB/ID vs TIER.NET vs DHIS
A3: =IF(Training!D4="","Enter inservice training otherwise DQA will be rejected","Training information recorded, well done!") -> Enter inservice training otherwise DQA will be rejected
A4: ='Power Query'!K3 -> TB cascade | B4: ='Power Query'!L3 -> Under 5yrs | C4: ='Power Query'!M3 -> Headcount | D4: ='Power Query'!O3 -> 0 | E4: ='Power Query'!O64 -> 0 | G4: ='Power Query'!Q3 -> 0 | H4: ='Power Query'!Q64 -> 0 | I4: {=IFERROR(_xlfn.IFS((H4-G4)/H4>0.05,"confirm if data is correct",(G4-H4)/G4>0.05,"confirm if data is correct"),"")} | J4: =IFERROR(IF(E4<>H4,"Summary sheet does not match DHIS, please investigate",""),"")
A5: ='Power Query'!K4 -> TB cascade | B5: ='Power Query'!L4 -> Under 5yrs | C5: ='Power Query'!M4 -> TB screening | D5: ='Power Query'!O4 -> 330 | E5: ='Power Query'!O65 -> 0 | G5: ='Power Query'!Q4 -> 0 | H5: ='Power Query'!Q65 -> 0 | I5: {=IFERROR(_xlfn.IFS((H5-G5)/H5>0.05,"confirm if data is correct",(G5-H5)/G5>0.05,"confirm if data is correct"),"")} | J5: =IFERROR(IF(E5<>H5,"Summary sheet does not match DHIS, please investigate",""),"")
A6: ='Power Query'!K5 -> TB cascade | B6: ='Power Query'!L5 -> Under 5yrs | C6: ='Power Query'!M5 -> Client eligible for TB test | D6: ='Power Query'!P5 -> 0 | E6: ='Power Query'!P66 -> 0 | F6: {=IFERROR(_xlfn.IFS((E6-D6)/E6>0.05,"confirm if data is correct",(D6-E6)/D6>0.05,"confirm if data is correct"),"")} | G6: ='Power Query'!Q5 -> 0 | H6: ='Power Query'!Q66 -> 0 | I6: {=IFERROR(_xlfn.IFS((H6-G6)/H6>0.05,"confirm if data is correct",(G6-H6)/G6>0.05,"confirm if data is correct"),"")} | J6: =IFERROR(IF(E6<>H6,"TIER.Net does not match DHIS, please investigate",""),"")
A7: ='Power Query'!K6 -> TB cascade | B7: ='Power Query'!L6 -> Under 5yrs | C7: ='Power Query'!M6 -> TB test using GeneXpert | D7: ='Power Query'!P6 -> 0 | E7: ='Power Query'!P67 -> 0 | F7: {=IFERROR(_xlfn.IFS((E7-D7)/E7>0.05,"confirm if data is correct",(D7-E7)/D7>0.05,"confirm if data is correct"),"")} | G7: ='Power Query'!Q6 -> 0 | H7: ='Power Query'!Q67 -> 0 | I7: {=IFERROR(_xlfn.IFS((H7-G7)/H7>0.05,"confirm if data is correct",(G7-H7)/G7>0.05,"confirm if data is correct"),"")} | J7: =IFERROR(IF(E7<>H7,"TIER.Net does not match DHIS, please investigate",""),"")
A8: ='Power Query'!K7 -> TB cascade | B8: ='Power Query'!L7 -> Under 5yrs | C8: ='Power Query'!M7 -> DS-TB clinically diagnosed | D8: ='Power Query'!P7 -> 0 | E8: ='Power Query'!P68 -> 0 | F8: =IFERROR(IF(E8>E9,"high clinical diagnosis investigate","clear"),"") -> clear | G8: ='Power Query'!Q7 -> 0 | H8: ='Power Query'!Q68 -> 0 | I8: =IFERROR(IF(H8>H9,"high clinical diagnosis investigate","clear"),"") -> clear | J8: =IFERROR(IF(E8<>H8,"TIER.Net does not match DHIS, please investigate",""),"")
A9: ='Power Query'!K8 -> TB cascade | B9: ='Power Query'!L8 -> Under 5yrs | C9: ='Power Query'!M8 -> DS-TB Bacteriologically confirmed | D9: ='Power Query'!P8 -> 0 | E9: ='Power Query'!P69 -> 0 | F9: =IFERROR(IF(E8>E9,"high clinical diagnosis investigate","clear"),"") -> clear | G9: ='Power Query'!Q8 -> 0 | H9: ='Power Query'!Q69 -> 0 | I9: =IFERROR(IF(H8>H9,"high clinical diagnosis investigate","clear"),"") -> clear | J9: =IFERROR(IF(E9<>H9,"TIER.Net does not match DHIS, please investigate",""),"")
A10: ='Power Query'!K9 -> TB cascade | B10: ='Power Query'!L9 -> Under 5yrs | C10: ='Power Query'!M9 -> RR-TB bacteriologically confirmed | D10: ='Power Query'!P9 -> 0 | E10: ='Power Query'!P70 -> 0 | F10: {=IFERROR(_xlfn.IFS((E10-D10)/E10>0.05,"confirm if data is correct",(D10-E10)/D10>0.05,"confirm if data is correct"),"")} | G10: ='Power Query'!Q9 -> 0 | H10: ='Power Query'!Q70 -> 0 | I10: {=IFERROR(_xlfn.IFS((H10-G10)/H10>0.05,"confirm if data is correct",(G10-H10)/G10>0.05,"confirm if data is correct"),"")} | J10: =IFERROR(IF(E10<>H10,"TIER.Net does not match DHIS, please investigate",""),"")
A11: ='Power Query'!K10 -> TB cascade | B11: ='Power Query'!L10 -> Under 5yrs | C11: ='Power Query'!M10 -> DSTB treatment start | D11: ='Power Query'!P10 -> 1 | E11: ='Power Query'!P71 -> 0 | F11: {=IFERROR(_xlfn.IFS((E11-D11)/E11>0.05,"confirm if data is correct",(D11-E11)/D11>0.05,"confirm if data is correct"),"")} | G11: ='Power Query'!Q10 -> 0 | H11: ='Power Query'!Q71 -> 0 | I11: {=IFERROR(_xlfn.IFS((H11-G11)/H11>0.05,"confirm if data is correct",(G11-H11)/G11>0.05,"confirm if data is correct"),"")} | J11: =IFERROR(IF(E11<>H11,"TIER.Net does not match DHIS, please investigate",""),"")
A12: ='Power Query'!K11 -> TB cascade | B12: ='Power Query'!L11 -> Under 5yrs | C12: ='Power Query'!M11 -> Number initial lost to follow-up | D12: ='Power Query'!P11 -> -1 | E12: ='Power Query'!P72 -> 0 | F12: {=IFERROR(_xlfn.IFS((E12-D12)/E12>0.05,"confirm if data is correct",(D12-E12)/D12>0.05,"confirm if data is correct"),"")} | G12: ='Power Query'!Q11 -> 0 | H12: ='Power Query'!Q72 -> 0 | I12: {=IFERROR(_xlfn.IFS((H12-G12)/H12>0.05,"confirm if data is correct",(G12-H12)/G12>0.05,"confirm if data is correct"),"")} | J12: =IFERROR(IF(E12<>H12,"TIER.Net does not match DHIS, please investigate",""),"")
A13: ='Power Query'!K12 -> TB cascade | B13: ='Power Query'!L12 -> Under 5yrs | C13: ='Power Query'!M12 -> NHLS ALERTS DS-TB | D13: ='Power Query'!P12 -> 0 | E13: ='Power Query'!P73 -> 0 | F13: {=IFERROR(_xlfn.IFS((E13-D13)/E13>0.05,"confirm if data is correct",(D13-E13)/D13>0.05,"confirm if data is correct"),"")} | G13: ='Power Query'!Q12 -> 0 | H13: ='Power Query'!Q73 -> 0 | I13: {=IFERROR(_xlfn.IFS((H13-G13)/H13>0.05,"confirm if data is correct",(G13-H13)/G13>0.05,"confirm if data is correct"),"")} | J13: =IFERROR(IF(E13<>H13,"TIER.Net does not match DHIS, please investigate",""),"")
A14: ='Power Query'!K13 -> TPT | B14: ='Power Query'!L13 -> Under 5yrs | C14: ='Power Query'!M13 -> TB contact | D14: ='Power Query'!N13 -> 0 | E14: ='Power Query'!N74 -> 0 | F14: {=IFERROR(_xlfn.IFS((E14-D14)/E14>0.05,"confirm if data is correct",(D14-E14)/D14>0.05,"confirm if data is correct"),"")} | G14: ='Power Query'!Q13 -> 0 | H14: ='Power Query'!Q74 -> 0 | I14: {=IFERROR(_xlfn.IFS((H14-G14)/H14>0.05,"confirm if data is correct",(G14-H14)/G14>0.05,"confirm if data is correct"),"")} | J14: =IFERROR(IF(E14<>H14,"TB ID does not match DHIS, please investigate",""),"")
A15: ='Power Query'!K14 -> TPT | B15: ='Power Query'!L14 -> Under 5yrs | C15: ='Power Query'!M14 -> TB contact start on TPT | D15: ='Power Query'!N14 -> 0 | E15: ='Power Query'!N75 -> 0 | F15: {=IFERROR(_xlfn.IFS((E15-D15)/E15>0.05,"confirm if data is correct",(D15-E15)/D15>0.05,"confirm if data is correct"),"")} | G15: ='Power Query'!Q14 -> 0 | H15: ='Power Query'!Q75 -> 0 | I15: {=IFERROR(_xlfn.IFS((H15-G15)/H15>0.05,"confirm if data is correct",(G15-H15)/G15>0.05,"confirm if data is correct"),"")} | J15: =IFERROR(IF(E15<>H15,"TB ID does not match DHIS, please investigate",""),"")
A16: ='Power Query'!K15 -> TPT | B16: ='Power Query'!L15 -> All ages | C16: ='Power Query'!M15 -> PLWHIV on ART eligible for TPT | D16: ='Power Query'!N15 -> 0 | E16: ='Power Query'!N76 -> 0 | F16: {=IFERROR(_xlfn.IFS((E16-D16)/E16>0.05,"confirm if data is correct",(D16-E16)/D16>0.05,"confirm if data is correct"),"")} | G16: ='Power Query'!Q15 -> 0 | H16: ='Power Query'!Q76 -> 0 | I16: {=IFERROR(_xlfn.IFS((H16-G16)/H16>0.05,"confirm if data is correct",(G16-H16)/G16>0.05,"confirm if data is correct"),"")} | J16: =IFERROR(IF(E16<>H16,"TB ID does not match DHIS, please investigate",""),"")
A17: ='Power Query'!K16 -> TPT | B17: ='Power Query'!L16 -> All ages | C17: ='Power Query'!M16 -> PLWHIV on ART started TPT | D17: ='Power Query'!N16 -> 0 | E17: ='Power Query'!N77 -> 0 | F17: {=IFERROR(_xlfn.IFS((E17-D17)/E17>0.05,"confirm if data is correct",(D17-E17)/D17>0.05,"confirm if data is correct"),"")} | G17: ='Power Query'!Q16 -> 0 | H17: ='Power Query'!Q77 -> 0 | I17: {=IFERROR(_xlfn.IFS((H17-G17)/H17>0.05,"confirm if data is correct",(G17-H17)/G17>0.05,"confirm if data is correct"),"")} | J17: =IFERROR(IF(E17<>H17,"TB ID does not match DHIS, please investigate",""),"")
A18: ='Power Query'!K17 -> DSTB outcome | B18: ='Power Query'!L17 -> All ages | C18: ='Power Query'!M17 -> DSTB Treatment success | D18: ='Power Query'!P17 -> 0 | E18: ='Power Query'!P78 -> 0 | F18: {=IFERROR(_xlfn.IFS((E18-D18)/E18>0.05,"confirm if data is correct",(D18-E18)/D18>0.05,"confirm if data is correct"),"")} | G18: ='Power Query'!Q17 -> 0 | H18: ='Power Query'!Q78 -> 0 | I18: {=IFERROR(_xlfn.IFS((H18-G18)/H18>0.05,"confirm if data is correct",(G18-H18)/G18>0.05,"confirm if data is correct"),"")} | J18: =IFERROR(IF(E18<>H18,"TIER.Net does not match DHIS, please investigate",""),"")
A19: ='Power Query'!K18 -> DSTB outcome | B19: ='Power Query'!L18 -> All ages | C19: ='Power Query'!M18 -> DSTB LTFU | D19: ='Power Query'!P18 -> 0 | E19: ='Power Query'!P79 -> 0 | F19: {=IFERROR(_xlfn.IFS((E19-D19)/E19>0.05,"confirm if data is correct",(D19-E19)/D19>0.05,"confirm if data is correct"),"")} | G19: ='Power Query'!Q18 -> 0 | H19: ='Power Query'!Q79 -> 0 | I19: {=IFERROR(_xlfn.IFS((H19-G19)/H19>0.05,"confirm if data is correct",(G19-H19)/G19>0.05,"confirm if data is correct"),"")} | J19: =IFERROR(IF(E19<>H19,"TIER.Net does not match DHIS, please investigate",""),"")
A20: ='Power Query'!K19 -> DSTB outcome | B20: ='Power Query'!L19 -> All ages | C20: ='Power Query'!M19 -> DSTB Treatment Failure | D20: ='Power Query'!P19 -> 0 | E20: ='Power Query'!P80 -> 0 | F20: {=IFERROR(_xlfn.IFS((E20-D20)/E20>0.05,"confirm if data is correct",(D20-E20)/D20>0.05,"confirm if data is correct"),"")} | G20: ='Power Query'!Q19 -> 0 | H20: ='Power Query'!Q80 -> 0 | I20: {=IFERROR(_xlfn.IFS((H20-G20)/H20>0.05,"confirm if data is correct",(G20-H20)/G20>0.05,"confirm if data is correct"),"")} | J20: =IFERROR(IF(E20<>H20,"TIER.Net does not match DHIS, please investigate",""),"")
A21: ='Power Query'!K20 -> DSTB outcome | B21: ='Power Query'!L20 -> All ages | C21: ='Power Query'!M20 -> DSTB Died | D21: ='Power Query'!P20 -> 0 | E21: ='Power Query'!P81 -> 0 | F21: {=IFERROR(_xlfn.IFS((E21-D21)/E21>0.05,"confirm if data is correct",(D21-E21)/D21>0.05,"confirm if data is correct"),"")} | G21: ='Power Query'!Q20 -> 0 | H21: ='Power Query'!Q81 -> 0 | I21: {=IFERROR(_xlfn.IFS((H21-G21)/H21>0.05,"confirm if data is correct",(G21-H21)/G21>0.05,"confirm if data is correct"),"")} | J21: =IFERROR(IF(E21<>H21,"TIER.Net does not match DHIS, please investigate",""),"")
A22: ='Power Query'!K21 -> DSTB outcome | B22: ='Power Query'!L21 -> All ages | C22: ='Power Query'!M21 -> Not evaluated | D22: ='Power Query'!P21 -> 0 | E22: ='Power Query'!P82 -> 0 | F22: {=IFERROR(_xlfn.IFS((E22-D22)/E22>0.05,"confirm if data is correct",(D22-E22)/D22>0.05,"confirm if data is correct"),"")} | G22: ='Power Query'!Q21 -> 0 | H22: ='Power Query'!Q82 -> 0 | I22: {=IFERROR(_xlfn.IFS((H22-G22)/H22>0.05,"confirm if data is correct",(G22-H22)/G22>0.05,"confirm if data is correct"),"")} | J22: =IFERROR(IF(E22<>H22,"TIER.Net does not match DHIS, please investigate",""),"")
A23: ='Power Query'!K22 -> DSTB outcome | B23: ='Power Query'!L22 -> All ages | C23: ='Power Query'!M22 -> DSTB Total | D23: ='Power Query'!P22 -> 0 | E23: ='Power Query'!P83 -> 0 | F23: {=IFERROR(_xlfn.IFS((E23-D23)/E23>0.05,"confirm if data is correct",(D23-E23)/D23>0.05,"confirm if data is correct"),"")} | G23: ='Power Query'!Q22 -> 0 | H23: ='Power Query'!Q83 -> 0 | I23: {=IFERROR(_xlfn.IFS((H23-G23)/H23>0.05,"confirm if data is correct",(G23-H23)/G23>0.05,"confirm if data is correct"),"")} | J23: =IFERROR(IF(E23<>H23,"TIER.Net does not match DHIS, please investigate",""),"")
A24: ='Power Query'!K23 -> DSTB outcome | B24: ='Power Query'!L23 -> All ages | C24: ='Power Query'!M23 -> DSTB Transfer out (TFO) | D24: ='Power Query'!P23 -> 0 | E24: ='Power Query'!P84 -> 0 | F24: {=IFERROR(_xlfn.IFS((E24-D24)/E24>0.05,"confirm if data is correct",(D24-E24)/D24>0.05,"confirm if data is correct"),"")} | G24: ='Power Query'!Q23 -> 0 | H24: ='Power Query'!Q84 -> 0 | I24: {=IFERROR(_xlfn.IFS((H24-G24)/H24>0.05,"confirm if data is correct",(G24-H24)/G24>0.05,"confirm if data is correct"),"")} | J24: =IFERROR(IF(E24<>H24,"TIER.Net does not match DHIS, please investigate",""),"")
A25: ='Power Query'!K24 -> DSTB outcome | B25: ='Power Query'!L24 -> All ages | C25: ='Power Query'!M24 -> TB Rif resistant | D25: ='Power Query'!P24 -> 0 | E25: ='Power Query'!P85 -> 0 | F25: {=IFERROR(_xlfn.IFS((E25-D25)/E25>0.05,"confirm if data is correct",(D25-E25)/D25>0.05,"confirm if data is correct"),"")} | G25: ='Power Query'!Q24 -> 0 | H25: ='Power Query'!Q85 -> 0 | I25: {=IFERROR(_xlfn.IFS((H25-G25)/H25>0.05,"confirm if data is correct",(G25-H25)/G25>0.05,"confirm if data is correct"),"")} | J25: =IFERROR(IF(E25<>H25,"TIER.Net does not match DHIS, please investigate",""),"")
A26: ='Power Query'!K25 -> DSTB outcome | B26: ='Power Query'!L25 -> All ages | C26: ='Power Query'!M25 -> TB MDR | D26: ='Power Query'!P25 -> 0 | E26: ='Power Query'!P86 -> 0 | F26: {=IFERROR(_xlfn.IFS((E26-D26)/E26>0.05,"confirm if data is correct",(D26-E26)/D26>0.05,"confirm if data is correct"),"")} | G26: ='Power Query'!Q25 -> 0 | H26: ='Power Query'!Q86 -> 0 | I26: {=IFERROR(_xlfn.IFS((H26-G26)/H26>0.05,"confirm if data is correct",(G26-H26)/G26>0.05,"confirm if data is correct"),"")} | J26: =IFERROR(IF(E26<>H26,"TIER.Net does not match DHIS, please investigate",""),"")
A27: ='Power Query'!K26 -> DSTB outcome | B27: ='Power Query'!L26 -> All ages | C27: ='Power Query'!M26 -> TB Total all cases | D27: ='Power Query'!P26 -> 0 | E27: ='Power Query'!P87 -> 0 | F27: {=IFERROR(_xlfn.IFS((E27-D27)/E27>0.05,"confirm if data is correct",(D27-E27)/D27>0.05,"confirm if data is correct"),"")} | G27: ='Power Query'!Q26 -> 0 | H27: ='Power Query'!Q87 -> 0 | I27: {=IFERROR(_xlfn.IFS((H27-G27)/H27>0.05,"confirm if data is correct",(G27-H27)/G27>0.05,"confirm if data is correct"),"")} | J27: =IFERROR(IF(E27<>H27,"TIER.Net does not match DHIS, please investigate",""),"")
A28: ='Power Query'!K27 -> DSTB outcome | B28: ='Power Query'!L27 -> All ages | C28: ='Power Query'!M27 -> Duplicates found | D28: ='Power Query'!P27 -> 0 | E28: ='Power Query'!P88 -> 0 | F28: {=IFERROR(_xlfn.IFS((E28-D28)/E28>0.05,"confirm if data is correct",(D28-E28)/D28>0.05,"confirm if data is correct"),"")} | G28: ='Power Query'!Q27 -> 0 | H28: ='Power Query'!Q88 -> 0 | I28: {=IFERROR(_xlfn.IFS((H28-G28)/H28>0.05,"confirm if data is correct",(G28-H28)/G28>0.05,"confirm if data is correct"),"")} | J28: =IFERROR(IF(E28<>H28,"TIER.Net does not match DHIS, please investigate",""),"")
A29: ='Power Query'!K28 -> TB cascade | B29: ='Power Query'!L28 -> Over 5 years | C29: ='Power Query'!M28 -> Headcount | D29: ='Power Query'!O28 -> 0 | E29: ='Power Query'!O89 -> 0 | F29: {=IFERROR(_xlfn.IFS((E29-D29)/E29>0.05,"confirm if data is correct",(D29-E29)/D29>0.05,"confirm if data is correct"),"")} | G29: ='Power Query'!Q28 -> 0 | H29: ='Power Query'!Q89 -> 0 | I29: {=IFERROR(_xlfn.IFS((H29-G29)/H29>0.05,"confirm if data is correct",(G29-H29)/G29>0.05,"confirm if data is correct"),"")} | J29: =IFERROR(IF(E29<>H29,"Summary sheet does not match DHIS, please investigate",""),"")
A30: ='Power Query'!K29 -> TB cascade | B30: ='Power Query'!L29 -> Over 5 years | C30: ='Power Query'!M29 -> TB screening | D30: ='Power Query'!O29 -> 1967 | E30: ='Power Query'!O90 -> 0 | F30: {=IFERROR(_xlfn.IFS((E30-D30)/E30>0.05,"confirm if data is correct",(D30-E30)/D30>0.05,"confirm if data is correct"),"")} | G30: ='Power Query'!Q29 -> 0 | H30: ='Power Query'!Q90 -> 0 | I30: {=IFERROR(_xlfn.IFS((H30-G30)/H30>0.05,"confirm if data is correct",(G30-H30)/G30>0.05,"confirm if data is correct"),"")} | J30: =IFERROR(IF(E30<>H30,"Summary sheet does not match DHIS, please investigate",""),"")
A31: ='Power Query'!K30 -> TB cascade | B31: ='Power Query'!L30 -> Over 5 years | C31: ='Power Query'!M30 -> Client eligible for TB test | D31: ='Power Query'!P30 -> 0 | E31: ='Power Query'!P91 -> 0 | F31: {=IFERROR(_xlfn.IFS((E31-D31)/E31>0.05,"confirm if data is correct",(D31-E31)/D31>0.05,"confirm if data is correct"),"")} | G31: ='Power Query'!Q30 -> 0 | H31: ='Power Query'!Q91 -> 0 | I31: {=IFERROR(_xlfn.IFS((H31-G31)/H31>0.05,"confirm if data is correct",(G31-H31)/G31>0.05,"confirm if data is correct"),"")} | J31: =IFERROR(IF(E31<>H31,"TIER.Net does not match DHIS, please investigate",""),"")
A32: ='Power Query'!K31 -> TB cascade | B32: ='Power Query'!L31 -> Over 5 years | C32: ='Power Query'!M31 -> TB test using GeneXpert | D32: ='Power Query'!P31 -> 0 | E32: ='Power Query'!P92 -> 0 | F32: {=IFERROR(_xlfn.IFS((E32-D32)/E32>0.05,"confirm if data is correct",(D32-E32)/D32>0.05,"confirm if data is correct"),"")} | G32: ='Power Query'!Q31 -> 0 | H32: ='Power Query'!Q92 -> 0 | I32: {=IFERROR(_xlfn.IFS((H32-G32)/H32>0.05,"confirm if data is correct",(G32-H32)/G32>0.05,"confirm if data is correct"),"")} | J32: =IFERROR(IF(E32<>H32,"TIER.Net does not match DHIS, please investigate",""),"")
A33: ='Power Query'!K32 -> TB cascade | B33: ='Power Query'!L32 -> Over 5 years | C33: ='Power Query'!M32 -> DS-TB clinically diagnosed | D33: ='Power Query'!P32 -> 0 | E33: ='Power Query'!P93 -> 0 | F33: {=IFERROR(_xlfn.IFS((E33-D33)/E33>0.05,"confirm if data is correct",(D33-E33)/D33>0.05,"confirm if data is correct"),"")} | G33: ='Power Query'!Q32 -> 0 | H33: ='Power Query'!Q93 -> 0 | I33: {=IFERROR(_xlfn.IFS((H33-G33)/H33>0.05,"confirm if data is correct",(G33-H33)/G33>0.05,"confirm if data is correct"),"")} | J33: =IFERROR(IF(E33<>H33,"TIER.Net does not match DHIS, please investigate",""),"")
A34: ='Power Query'!K33 -> TB cascade | B34: ='Power Query'!L33 -> Over 5 years | C34: ='Power Query'!M33 -> DS-TB Bacteriologically confirmed | D34: ='Power Query'!P33 -> 0 | E34: ='Power Query'!P94 -> 0 | F34: {=IFERROR(_xlfn.IFS((E34-D34)/E34>0.05,"confirm if data is correct",(D34-E34)/D34>0.05,"confirm if data is correct"),"")} | G34: ='Power Query'!Q33 -> 0 | H34: ='Power Query'!Q94 -> 0 | I34: {=IFERROR(_xlfn.IFS((H34-G34)/H34>0.05,"confirm if data is correct",(G34-H34)/G34>0.05,"confirm if data is correct"),"")} | J34: =IFERROR(IF(E34<>H34,"TIER.Net does not match DHIS, please investigate",""),"")
A35: ='Power Query'!K34 -> TB cascade | B35: ='Power Query'!L34 -> Over 5 years | C35: ='Power Query'!M34 -> RR-TB bacteriologically confirmed | D35: ='Power Query'!P34 -> 0 | E35: ='Power Query'!P95 -> 0 | F35: {=IFERROR(_xlfn.IFS((E35-D35)/E35>0.05,"confirm if data is correct",(D35-E35)/D35>0.05,"confirm if data is correct"),"")} | G35: ='Power Query'!Q34 -> 0 | H35: ='Power Query'!Q95 -> 0 | I35: {=IFERROR(_xlfn.IFS((H35-G35)/H35>0.05,"confirm if data is correct",(G35-H35)/G35>0.05,"confirm if data is correct"),"")} | J35: =IFERROR(IF(E35<>H35,"TIER.Net does not match DHIS, please investigate",""),"")
A36: ='Power Query'!K35 -> TB cascade | B36: ='Power Query'!L35 -> Over 5 years | C36: ='Power Query'!M35 -> DSTB treatment start | D36: ='Power Query'!P35 -> 6 | E36: ='Power Query'!P96 -> 0 | F36: {=IFERROR(_xlfn.IFS((E36-D36)/E36>0.05,"confirm if data is correct",(D36-E36)/D36>0.05,"confirm if data is correct"),"")} | G36: ='Power Query'!Q35 -> 0 | H36: ='Power Query'!Q96 -> 0 | I36: {=IFERROR(_xlfn.IFS((H36-G36)/H36>0.05,"confirm if data is correct",(G36-H36)/G36>0.05,"confirm if data is correct"),"")} | J36: =IFERROR(IF(E36<>H36,"TIER.Net does not match DHIS, please investigate",""),"")
A37: ='Power Query'!K36 -> TB cascade | B37: ='Power Query'!L36 -> Over 5 years | C37: ='Power Query'!M36 -> Number initial lost to follow-up | D37: ='Power Query'!P36 -> -6 | E37: ='Power Query'!P97 -> 0 | F37: {=IFERROR(_xlfn.IFS((E37-D37)/E37>0.05,"confirm if data is correct",(D37-E37)/D37>0.05,"confirm if data is correct"),"")} | G37: ='Power Query'!Q36 -> 0 | H37: ='Power Query'!Q97 -> 0 | I37: {=IFERROR(_xlfn.IFS((H37-G37)/H37>0.05,"confirm if data is correct",(G37-H37)/G37>0.05,"confirm if data is correct"),"")} | J37: =IFERROR(IF(E37<>H37,"TIER.Net does not match DHIS, please investigate",""),"")
A38: ='Power Query'!K37 -> TB cascade | B38: ='Power Query'!L37 -> Over 5 years | C38: ='Power Query'!M37 -> NHLS ALERTS DS-TB | D38: ='Power Query'!P37 -> 0 | E38: ='Power Query'!P98 -> 0 | F38: {=IFERROR(_xlfn.IFS((E38-D38)/E38>0.05,"confirm if data is correct",(D38-E38)/D38>0.05,"confirm if data is correct"),"")} | G38: ='Power Query'!Q37 -> 0 | H38: ='Power Query'!Q98 -> 0 | I38: {=IFERROR(_xlfn.IFS((H38-G38)/H38>0.05,"confirm if data is correct",(G38-H38)/G38>0.05,"confirm if data is correct"),"")} | J38: =IFERROR(IF(E38<>H38,"TIER.Net does not match DHIS, please investigate",""),"")
A39: ='Power Query'!K38 -> TPT | B39: ='Power Query'!L38 -> Over 5 years | C39: ='Power Query'!M38 -> TB contact | D39: ='Power Query'!N38 -> 0 | E39: ='Power Query'!N99 -> 0 | F39: =IF((D33+D34+D8+D9+D10+D35)>D39,"few contacts but high index, encourage contact tracing","clear") -> clear | G39: ='Power Query'!Q38 -> 0 | H39: ='Power Query'!Q99 -> 0 | I39: =IF((G33+G34+G8+G9+G10+G35)>G39,"few contacts but high index, encourage contact tracing","clear") -> clear | J39: =IFERROR(IF(E39<>H39,"TIER.Net does not match DHIS, please investigate",""),"")
A40: ='Power Query'!K39 -> TPT | B40: ='Power Query'!L39 -> Over 5 years | C40: ='Power Query'!M39 -> TB contact start on TPT | D40: ='Power Query'!N39 -> 0 | E40: ='Power Query'!N100 -> 0 | F40: =IF((D34+D35+D9+D10+D8+D33)>D40,"few contacts but high index, encourage TPT","clear") -> clear | G40: ='Power Query'!Q39 -> 0 | H40: ='Power Query'!Q100 -> 0 | I40: =IF((G34+G35+G9+G10+G8+G33)>G40,"few contacts but high index, encourage TPT","clear") -> clear | J40: =IFERROR(IF(E40<>H40,"TB ID does not match DHIS, please investigate",""),"")
...

Sheet TB stationery checklist
B3: Name of stationery | C3: Period of verification | D3: Availability | E3: Stationery version (year) | F3: Comments
B4: Intergrated file
B5: TB Identification register (DS-TB)
B6: DR-TB Identification register (DR-TB)
B7: PHC comprehensive tick register
B8: Summary sheet
B9: TPT register
B10: Contact line list register
B11: Tranfer out register

Sheet Before
B3: Dataset: | C3: Before | D3: Activity | E3: Monthly DQA | F3: TB type | G3: DS-TB
B4: Staff name | C4: Zolile Nonzapa | D4: Soweto Clinic
B5: Date of Visit | D5: NMB | F5: Authority | G5: doh
B6: Two months back: specify month | C6: Oct | D6: A
B9: TB Cascade
B10: Work on data 2 months back for this section | C10: Tally sheet/TIR/TB register | E10: Monthly Summary Sheet | G10: Check | I10: TIER.Net | K10: Check | M10: DHIS | O10: Check
C11: Under 5yrs | D11: 5yrs & odler | E11: Under 5yrs | F11: Over 5yrs | G11: Under 5yrs | H11: Over 5yrs | I11: Under 5yrs | J11: Over 5yrs | K11: Under 5yrs | L11: Over 5yrs | M11: Under 5yrs | N11: Over 5yrs | O11: Under 5yrs | P11: Over 5yrs | Q11: Comments
B12: Headcount | G12: =IF(C12=E12, "data is correct", "correct data") -> data is correct | H12: =IF(D12=F12, "data is correct", "correct data") -> data is correct | O12: =IF(E12=M12, "data is correct", "correct data") -> data is correct | P12: =IF(J12=N12, "data is correct", "correct data") -> data is correct
B13: TB screening | C13: 330 | D13: 1967 | E13: 330 | F13: 1967 | G13: =IF(C13=E13, "data is correct", "correct data") -> data is correct | H13: =IF(D13=F13, "data is correct", "correct data") -> data is correct | O13: =IF(E13=M13, "data is correct", "correct data") -> correct data | P13: =IF(J13=N13, "data is correct", "correct data") -> data is correct
B14: TB screening rate | C14: =IFERROR(C13/C12,"N/A") -> N/A | D14: =IFERROR(D13/D12,"N/A") -> N/A | E14: =IFERROR(E13/E12,"N/A") -> N/A | F14: =IFERROR(F13/F12,"N/A") -> N/A | I14: =IFERROR(I13/I12,"N/A") -> N/A | J14: =IFERROR(J13/J12,"N/A") -> N/A | M14: =IFERROR(M13/M12,"N/A") -> N/A | N14: =IFERROR(N13/N12,"N/A") -> N/A
B15: Client eligible for TB test | C15: 0 | D15: 121 | E15: 0 | F15: 121 | G15: =IF(C15=E15, "data is correct", "correct data") -> data is correct | H15: =IF(D15=F15, "data is correct", "correct data") -> data is correct | K15: =IF(E15=I15, "data is correct", "correct data") -> data is correct | L15: =IF(F15=J15, "data is correct", "correct data") -> correct data | O15: =IF(I15=M15, "data is correct", "correct data") -> data is correct | P15: =IF(J15=N15, "data is correct", "correct data") -> data is correct
B16: TB presumptive rate | C16: =IFERROR(C15/E13,"N/A") -> 0 | D16: =IFERROR(D15/F13,"N/A") -> 0.061514997 | E16: =IFERROR(E15/G13,"N/A") -> N/A | F16: =IFERROR(F15/H13,"N/A") -> N/A | I16: =IFERROR(I15/I13,"N/A") -> N/A | J16: =IFERROR(J15/J13,"N/A") -> N/A | M16: =IFERROR(M15/M13,"N/A") -> N/A | N16: =IFERROR(N15/N13,"N/A") -> N/A
B17: TB test using GeneXpert | C17: 0 | D17: 119 | E17: 0 | F17: 119 | G17: =IF(C17=E17, "data is correct", "correct data") -> data is correct | H17: =IF(D17=F17, "data is correct", "correct data") -> data is correct | K17: =IF(E17=I17, "data is correct", "correct data") -> data is correct | L17: =IF(F17=J17, "data is correct", "correct data") -> correct data | O17: =IF(I17=M17, "data is correct", "correct data") -> data is correct | P17: =IF(J17=N17, "data is correct", "correct data") -> data is correct
B18: DS-TB clinically diagnosed | C18: 0 | D18: 1 | E18: 0 | F18: 1 | G18: =IF(C18=E18, "data is correct", "correct data") -> data is correct | H18: =IF(D18=F18, "data is correct", "correct data") -> data is correct | K18: =IF(E18=I18, "data is correct", "correct data") -> data is correct | L18: =IF(F18=J18, "data is correct", "correct data") -> correct data | O18: =IF(I18=M18, "data is correct", "correct data") -> data is correct | P18: =IF(J18=N18, "data is correct", "correct data") -> data is correct
B19: DS-TB Bacteriologically confirmed | C19: 0 | D19: 20 | E19: 0 | F19: 20 | G19: =IF(C19=E19, "data is correct", "correct data") -> data is correct | H19: =IF(D19=F19, "data is correct", "correct data") -> data is correct | K19: =IF(E19=I19, "data is correct", "correct data") -> data is correct | L19: =IF(F19=J19, "data is correct", "correct data") -> correct data | O19: =IF(I19=M19, "data is correct", "correct data") -> data is correct | P19: =IF(J19=N19, "data is correct", "correct data") -> data is correct
B20: RR-TB bacteriologically confirmed | C20: 0 | D20: 2 | E20: 0 | F20: 2 | G20: =IF(C20=E20, "data is correct", "correct data") -> data is correct | H20: =IF(D20=F20, "data is correct", "correct data") -> data is correct | K20: =IF(E20=I20, "data is correct", "correct data") -> data is correct | L20: =IF(F20=J20, "data is correct", "correct data") -> correct data | O20: =IF(I20=M20, "data is correct", "correct data") -> data is correct | P20: =IF(J20=N20, "data is correct", "correct data") -> data is correct
B21: DSTB confirmation rate | C21: =IFERROR((C18+C19)/C15,"N/A") -> N/A | D21: =IFERROR((D18+D19)/D15,"N/A") -> 0.17355372 | E21: =IFERROR((E18+E19)/E15,"N/A") -> N/A | F21: =IFERROR((F18+F19)/F15,"N/A") -> 0.17355372 | I21: =IFERROR((I18+I19)/I15,"N/A") -> N/A | J21: =IFERROR((J18+J19)/J15,"N/A") -> N/A | M21: =IFERROR((M18+M19)/M15,"N/A") -> N/A | N21: =IFERROR((N18+N19)/N15,"N/A") -> N/A
B22: DSTB treatment start | C22: 0 | D22: 20 | E22: 0 | F22: 20 | G22: =IF(C22=E22, "data is correct", "correct data") -> data is correct | H22: =IF(D22=F22, "data is correct", "correct data") -> data is correct | I22: 1 | J22: 6 | K22: =IF(E22=I22, "data is correct", "correct data") -> correct data | L22: =IF(F22=J22, "data is correct", "correct data") -> correct data | O22: =IF(I22=M22, "data is correct", "correct data") -> correct data | P22: =IF(J22=N22, "data is correct", "correct data") -> correct data
B23: DSTB Treatment start rate | C23: =IFERROR(C22/(C18+C19),"N/A") -> N/A | D23: =IFERROR(D22/(D18+D19),"N/A") -> 0.95238095 | E23: =IFERROR(E22/(E18+E19),"N/A") -> N/A | F23: =IFERROR(F22/(F18+F19),"N/A") -> 0.95238095 | I23: =IFERROR(I22/(I18+I19),"N/A") -> N/A | J23: =IFERROR(J22/(J18+J19),"N/A") -> N/A | M23: =IFERROR(M22/(M18+M19),"N/A") -> N/A | N23: =IFERROR(N22/(N18+N19),"N/A") -> N/A
B24: Number initial lost to follow-up | C24: =(C18+C19)-C22 -> 0 | D24: =(D18+D19)-D22 -> 1 | E24: =(E18+E19)-E22 -> 0 | F24: =(F18+F19)-F22 -> 1 | G24: =IF(C24=E24, "data is correct", "correct data") -> data is correct | H24: =IF(D24=F24, "data is correct", "correct data") -> data is correct | I24: =(I18+I19)-I22 -> -1 | J24: =(J18+J19)-J22 -> -6 | K24: =IF(E24=I24, "data is correct", "correct data") -> correct data | L24: =IF(F24=J24, "data is correct", "correct data") -> correct data | M24: =(M18+M19)-M22 -> 0 | N24: =(N18+N19)-N22 -> 0 | O24: =IF(I24=M24, "data is correct", "correct data") -> correct data | P24: =IF(J24=N24, "data is correct", "correct data") -> correct data
B25: Initial lost to follow up rate | C25: =IFERROR(C24/C22,"N/A") -> N/A | D25: =IFERROR(D24/D22,"N/A") -> 0.05 | E25: =IFERROR(E24/E22,"N/A") -> N/A | F25: =IFERROR(F24/F22,"N/A") -> 0.05 | I25: =IFERROR(I24/I22,"N/A") -> -1 | J25: =IFERROR(J24/J22,"N/A") -> -1 | M25: =IFERROR(M24/M22,"N/A") -> N/A | N25: =IFERROR(N24/N22,"N/A") -> N/A
B26: Count alerts for facility | C26: Under 5yrs alerts | D26: 5yrs & older alerts
B27: NHLS ALERTS DS-TB
B28: NHLS ALERT START RATE | C28: =IF(C19=C27,"data is correct","update TIR with correct number") -> data is correct | D28: =IF(D19=D27,"data is correct","update TIR with correct number") -> update TIR with correct number
C30: Tally sheet/TIR/TB register | E30: Monthly Summary Sheet | I30: TIER.Net/PHCIS/PreHMIS | M30: DHIS | O30: Check
B31: TB TPT | C31: Under 5yrs | D31: 5yrs & odler | E31: Under 5yrs | F31: Over 5yrs | I31: Under 5yrs | J31: Over 5yrs | M31: Under 5yrs | N31: Over 5yrs | O31: Under 5yrs | P31: Over 5yrs
B32: TB contact | C32: 0 | D32: 0 | G32: =IF(C32=E32, "data is correct", "correct data") -> data is correct | H32: =IF(D32=F32, "data is correct", "correct data") -> data is correct | K32: =IF(E32=I32, "data is correct", "correct data") -> data is correct | L32: =IF(F32=J32, "data is correct", "correct data") -> data is correct | O32: =IF(E32=M32, "data is correct", "correct data") -> data is correct | P32: =IF(F32=N32, "data is correct", "correct data") -> data is correct
B33: TB contact start on TPT | C33: 0 | D33: 0 | G33: =IF(C33=E33, "data is correct", "correct data") -> data is correct | H33: =IF(D33=F33, "data is correct", "correct data") -> data is correct | K33: =IF(E33=I33, "data is correct", "correct data") -> data is correct | L33: =IF(F33=J33, "data is correct", "correct data") -> data is correct | O33: =IF(E33=M33, "data is correct", "correct data") -> data is correct | P33: =IF(F33=N33, "data is correct", "correct data") -> data is correct
B34: TPT initiation rate | C34: =IFERROR(C33/C32,"N/A") -> N/A | D34: =IFERROR(D33/D32,"N/A") -> N/A | E34: =IFERROR(E33/E32,"N/A") -> N/A | F34: =IFERROR(F33/F32,"N/A") -> N/A | I34: =IFERROR(I33/I32,"N/A") -> N/A | J34: =IFERROR(J33/J32,"N/A") -> N/A | M34: =IFERROR(M33/M32,"N/A") -> N/A | N34: =IFERROR(N33/N32,"N/A") -> N/A
B35: HIV TPT
B36: PLWHIV on ART eligible for TPT | C36: 0 | D36: 0 | G36: =IF(A36=E36, "data is correct", "correct data") -> data is correct | H36: =IF(B36=F36, "data is correct", "correct data") -> correct data | K36: =IF(E36=I36, "data is correct", "correct data") -> data is correct | L36: =IF(F36=J36, "data is correct", "correct data") -> data is correct | O36: =IF(E36=M36, "data is correct", "correct data") -> data is correct | P36: =IF(F36=N36, "data is correct", "correct data") -> data is correct
B37: PLWHIV on ART started TPT | C37: 0 | D37: 0 | G37: =IF(A37=E37, "data is correct", "correct data") -> data is correct | H37: =IF(B37=F37, "data is correct", "correct data") -> correct data | K37: =IF(E37=I37, "data is correct", "correct data") -> data is correct | L37: =IF(F37=J37, "data is correct", "correct data") -> data is correct | O37: =IF(E37=M37, "data is correct", "correct data") -> data is correct | P37: =IF(F37=N37, "data is correct", "correct data") -> data is correct
B38: PLWHIV on ART started TPT rate | C38: =IFERROR(C37/C36,"N/A") -> N/A | D38: =IFERROR(D37/D36,"N/A") -> N/A | E38: =IFERROR(E37/E36,"N/A") -> N/A | F38: =IFERROR(F37/F36,"N/A") -> N/A | I38: =IFERROR(I37/I36,"N/A") -> N/A | J38: =IFERROR(J37/J36,"N/A") -> N/A | M38: =IFERROR(M37/M36,"N/A") -> N/A | N38: =IFERROR(N37/N36,"N/A") -> N/A
B40: Work on data current data for this section
B41: Tier.Net/PHCIS/PreHMIS TB reports
C42: Number | D42: Comments
B43: TB identification results outstanding list
B44: Waiting for TB treatment list
B45: DSTB coversion sputa required list
B46: DSTB discharge sputa required list
...

Sheet After
B3: Dataset: | C3: After | D3: Activity | E3: Monthly DQA | F3: TB type | G3: DS-TB
B4: Staff name | C4: Nkadimeng Rantsolase | D4: Facility Name | E4: Empilisweni CHC
B5: Date of Visit | C5: 45505 | D5: District | E5: Sedibeng | F5: Authority
B6: Two months back: specify month | C6: 45444 | D6: Sub-district | E6: Emfuleni
B9: TB Cascade
B10: Work on data 2 months back for this section | C10: Tally sheet/TIR/TB register | E10: Routine Monthly report | G10: Check | I10: TIER.Net | K10: Check | M10: DHIS | O10: Check
C11: Under 5yrs | D11: 5yrs & odler | E11: Under 5yrs | F11: Over 5yrs | G11: Under 5yrs | H11: Over 5yrs | I11: Under 5yrs | J11: Over 5yrs | K11: Under 5yrs | L11: Over 5yrs | M11: Under 5yrs | N11: Over 5yrs | O11: Under 5yrs | P11: Over 5yrs | Q11: Comments
B12: Headcount | G12: =IF(C12=E12, "data is correct", "correct data") -> data is correct | H12: =IF(D12=F12, "data is correct", "correct data") -> data is correct | O12: =IF(E12=M12, "data is correct", "correct data") -> data is correct | P12: =IF(F12=N12, "data is correct", "correct data") -> data is correct
B13: TB screening | G13: =IF(C13=E13, "data is correct", "correct data") -> data is correct | H13: =IF(D13=F13, "data is correct", "correct data") -> data is correct | O13: =IF(E13=M13, "data is correct", "correct data") -> data is correct | P13: =IF(F13=N13, "data is correct", "correct data") -> data is correct
B14: TB screening rate | C14: =IFERROR(C13/C12,"N/A") -> N/A | D14: =IFERROR(D13/D12,"N/A") -> N/A | E14: =IFERROR(E13/E12,"N/A") -> N/A | F14: =IFERROR(F13/F12,"N/A") -> N/A | I14: =IFERROR(I13/I12,"N/A") -> N/A | J14: =IFERROR(J13/J12,"N/A") -> N/A | M14: =IFERROR(M13/M12,"N/A") -> N/A | N14: =IFERROR(N13/N12,"N/A") -> N/A
B15: Client eligible for TB test | G15: =IF(C15=E15, "data is correct", "correct data") -> data is correct | H15: =IF(D15=F15, "data is correct", "correct data") -> data is correct | K15: =IF(E15=I15, "data is correct", "correct data") -> data is correct | L15: =IF(F15=J15, "data is correct", "correct data") -> data is correct | O15: =IF(I15=M15, "data is correct", "correct data") -> data is correct | P15: =IF(J15=N15, "data is correct", "correct data") -> data is correct
B16: TB presumptive rate | C16: =IFERROR(C15/C13,"N/A") -> N/A | D16: =IFERROR(D15/D13,"N/A") -> N/A | E16: =IFERROR(E15/E13,"N/A") -> N/A | F16: =IFERROR(F15/F13,"N/A") -> N/A | I16: =IFERROR(I15/I13,"N/A") -> N/A | J16: =IFERROR(J15/J13,"N/A") -> N/A | M16: =IFERROR(M15/M13,"N/A") -> N/A | N16: =IFERROR(N15/N13,"N/A") -> N/A
B17: TB test using GeneXpert | G17: =IF(C17=E17, "data is correct", "correct data") -> data is correct | H17: =IF(D17=F17, "data is correct", "correct data") -> data is correct | K17: =IF(E17=I17, "data is correct", "correct data") -> data is correct | L17: =IF(F17=J17, "data is correct", "correct data") -> data is correct | O17: =IF(I17=M17, "data is correct", "correct data") -> data is correct | P17: =IF(J17=N17, "data is correct", "correct data") -> data is correct
B18: DS-TB clinically diagnosed | G18: =IF(C18=E18, "data is correct", "correct data") -> data is correct | H18: =IF(D18=F18, "data is correct", "correct data") -> data is correct | K18: =IF(E18=I18, "data is correct", "correct data") -> data is correct | L18: =IF(F18=J18, "data is correct", "correct data") -> data is correct | O18: =IF(I18=M18, "data is correct", "correct data") -> data is correct | P18: =IF(J18=N18, "data is correct", "correct data") -> data is correct
B19: DS-TB Bacteriologically confirmed | G19: =IF(C19=E19, "data is correct", "correct data") -> data is correct | H19: =IF(D19=F19, "data is correct", "correct data") -> data is correct | K19: =IF(E19=I19, "data is correct", "correct data") -> data is correct | L19: =IF(F19=J19, "data is correct", "correct data") -> data is correct | O19: =IF(I19=M19, "data is correct", "correct data") -> data is correct | P19: =IF(J19=N19, "data is correct", "correct data") -> data is correct
B20: RR-TB bacteriologically confirmed | G20: =IF(C20=E20, "data is correct", "correct data") -> data is correct | H20: =IF(D20=F20, "data is correct", "correct data") -> data is correct | K20: =IF(E20=I20, "data is correct", "correct data") -> data is correct | L20: =IF(F20=J20, "data is correct", "correct data") -> data is correct | O20: =IF(I20=M20, "data is correct", "correct data") -> data is correct | P20: =IF(J20=N20, "data is correct", "correct data") -> data is correct
B21: DSTB confirmation rate | C21: =IFERROR((C18+C19)/C15,"N/A") -> N/A | D21: =IFERROR((D18+D19)/D15,"N/A") -> N/A | E21: =IFERROR((E18+E19)/E15,"N/A") -> N/A | F21: =IFERROR((F18+F19)/F15,"N/A") -> N/A | I21: =IFERROR((I18+I19)/I15,"N/A") -> N/A | J21: =IFERROR((J18+J19)/J15,"N/A") -> N/A | M21: =IFERROR((M18+M19)/M15,"N/A") -> N/A | N21: =IFERROR((N18+N19)/N15,"N/A") -> N/A
B22: DSTB treatment start | G22: =IF(C22=E22, "data is correct", "correct data") -> data is correct | H22: =IF(D22=F22, "data is correct", "correct data") -> data is correct | K22: =IF(E22=I22, "data is correct", "correct data") -> data is correct | L22: =IF(F22=J22, "data is correct", "correct data") -> data is correct | O22: =IF(I22=M22, "data is correct", "correct data") -> data is correct | P22: =IF(J22=N22, "data is correct", "correct data") -> data is correct
B23: DSTB Treatment start rate | C23: =IFERROR(C22/(C18+C19),"N/A") -> N/A | D23: =IFERROR(D22/(D18+D19),"N/A") -> N/A | E23: =IFERROR(E22/(E18+E19),"N/A") -> N/A | F23: =IFERROR(F22/(F18+F19),"N/A") -> N/A | I23: =IFERROR(I22/(I18+I19),"N/A") -> N/A | J23: =IFERROR(J22/(J18+J19),"N/A") -> N/A | M23: =IFERROR(M22/(M18+M19),"N/A") -> N/A | N23: =IFERROR(N22/(N18+N19),"N/A") -> N/A
B24: Number initial lost to follow-up | C24: =(C18+C19)-C22 -> 0 | D24: =(D18+D19)-D22 -> 0 | E24: =(E18+E19)-E22 -> 0 | F24: =(F18+F19)-F22 -> 0 | G24: =IF(C24=E24, "data is correct", "correct data") -> data is correct | H24: =IF(D24=F24, "data is correct", "correct data") -> data is correct | I24: =(I18+I19)-I22 -> 0 | J24: =(J18+J19)-J22 -> 0 | K24: =IF(E24=I24, "data is correct", "correct data") -> data is correct | L24: =IF(F24=J24, "data is correct", "correct data") -> data is correct | M24: =(M18+M19)-M22 -> 0 | N24: =(N18+N19)-N22 -> 0 | O24: =IF(I24=M24, "data is correct", "correct data") -> data is correct | P24: =IF(J24=N24, "data is correct", "correct data") -> data is correct
B25: Initial lost to follow up rate | C25: =IFERROR(C24/C22,"N/A") -> N/A | D25: =IFERROR(D24/D22,"N/A") -> N/A | E25: =IFERROR(E24/E22,"N/A") -> N/A | F25: =IFERROR(F24/F22,"N/A") -> N/A | I25: =IFERROR(I24/I22,"N/A") -> N/A | J25: =IFERROR(J24/J22,"N/A") -> N/A | M25: =IFERROR(M24/M22,"N/A") -> N/A | N25: =IFERROR(N24/N22,"N/A") -> N/A
B26: Count alerts for facility | C26: Under 5yrs alerts | D26: 5yrs & older alerts
B27: NHLS ALERTS DS-TB
B28: NHLS ALERT START RATE | C28: =IF(C19=C27,"data is correct","update TIR with correct number") -> data is correct | D28: =IF(D17=D27,"data is correct","update TIR with correct number") -> data is correct
C30: Tally sheet/TIR/TB register | E30: Routine Monthly report | I30: TIER.Net/PHCIS/PreHMIS | M30: DHIS | O30: Check
B31: TB TPT | C31: Under 5yrs | D31: 5yrs & odler | E31: Under 5yrs | F31: Over 5yrs | I31: Under 5yrs | J31: Over 5yrs | M31: Under 5yrs | N31: Over 5yrs | O31: Under 5yrs | P31: Over 5yrs
B32: TB contact | G32: =IF(C32=E32, "data is correct", "correct data") -> data is correct | H32: =IF(D32=F32, "data is correct", "correct data") -> data is correct | K32: =IF(E32=I32, "data is correct", "correct data") -> data is correct | L32: =IF(F32=J32, "data is correct", "correct data") -> data is correct | O32: =IF(E32=M32, "data is correct", "correct data") -> data is correct | P32: =IF(F32=N32, "data is correct", "correct data") -> data is correct
B33: TB contact start on TPT | G33: =IF(C33=E33, "data is correct", "correct data") -> data is correct | H33: =IF(D33=F33, "data is correct", "correct data") -> data is correct | K33: =IF(E33=I33, "data is correct", "correct data") -> data is correct | L33: =IF(F33=J33, "data is correct", "correct data") -> data is correct | O33: =IF(E33=M33, "data is correct", "correct data") -> data is correct | P33: =IF(F33=N33, "data is correct", "correct data") -> data is correct
B34: TPT initiation rate | C34: =IFERROR(C33/C32,"N/A") -> N/A | D34: =IFERROR(D33/D32,"N/A") -> N/A | E34: =IFERROR(E33/E32,"N/A") -> N/A | F34: =IFERROR(F33/F32,"N/A") -> N/A | I34: =IFERROR(I33/I32,"N/A") -> N/A | J34: =IFERROR(J33/J32,"N/A") -> N/A | M34: =IFERROR(M33/M32,"N/A") -> N/A | N34: =IFERROR(N33/N32,"N/A") -> N/A
B35: HIV TPT
B36: PLWHIV on ART eligible for TPT | G36: =IF(A36=E36, "data is correct", "correct data") -> data is correct | H36: =IF(B36=F36, "data is correct", "correct data") -> correct data | K36: =IF(E36=I36, "data is correct", "correct data") -> data is correct | L36: =IF(F36=J36, "data is correct", "correct data") -> data is correct | O36: =IF(E36=M36, "data is correct", "correct data") -> data is correct | P36: =IF(F36=N36, "data is correct", "correct data") -> data is correct
B37: PLWHIV on ART started TPT | G37: =IF(A37=E37, "data is correct", "correct data") -> data is correct | H37: =IF(B37=F37, "data is correct", "correct data") -> correct data | K37: =IF(E37=I37, "data is correct", "correct data") -> data is correct | L37: =IF(F37=J37, "data is correct", "correct data") -> data is correct | O37: =IF(E37=M37, "data is correct", "correct data") -> data is correct | P37: =IF(F37=N37, "data is correct", "correct data") -> data is correct
B38: PLWHIV on ART started TPT rate | C38: =IFERROR(C37/C36,"N/A") -> N/A | D38: =IFERROR(D37/D36,"N/A") -> N/A | E38: =IFERROR(E37/E36,"N/A") -> N/A | F38: =IFERROR(F37/F36,"N/A") -> N/A | I38: =IFERROR(I37/I36,"N/A") -> N/A | J38: =IFERROR(J37/J36,"N/A") -> N/A | M38: =IFERROR(M37/M36,"N/A") -> N/A | N38: =IFERROR(N37/N36,"N/A") -> N/A
B40: Work on data 2 months back for this section
B41: Tier.Net/PHCIS/PreHMIS TB reports
C42: Number | D42: Comments
B43: TB identification results outstanding list
B44: Waiting for TB treatment list
B45: DSTB coversion sputa required list
B46: DSTB discharge sputa required list
...

Sheet Training
A2: Training / Mentorship / orientation [Training Content : TIER.Net DHIS - specify]
A3: Aurum Staff Initials | B3: Date of Visit | C3: Type of intervention | D3: Training / Mentorship content | G3: DoH Staff Name | H3: Title of staff trained | J3: Outcome and time spent on in-service training / mentorship | T3: Follow up visit Date

Sheet Training validation sheet
E1: Period
B2: Training validation topic | E2: Oct 2024 -Apr 2025 | G2: 1
B3: TIER.Net data capturing | E3: Apr 2025 -Sep 2025 | G3: 0
B4: ICD10 codes
B5: Updating clinical stationery
B6: QIP development
B7: TD ID completion
B8: DHIS data verification
B9: TIER.Net & DHIS triangulation
B10: Monthly feedback
B11: DQA best practices
B12: Verification of monthly data on DHIS

Sheet Power  Query
B2: Activity | C2: TB type | D2: Dataset | E2: Staff name | F2: Date of visit | G2: District | H2: Sub-district | I2: Facility Name | J2: Authority | K2: Data type | L2: Age category | M2: Element | N2: CIR/TB register | O2: RMR | P2: TIER.Net | Q2: DHIS | R2: Staff trained | S2: Content of training/mentorship | T2: Staff position | U2: Stationery version | V2: Comments regarding sationery
B3: =Before!E$3 -> Monthly DQA | C3: =Before!G$3 -> DS-TB | D3: =Before!C$3 -> Before | E3: =Before!$C$4 -> Zolile Nonzapa | F3: =Before!$C$5 -> 0 | G3: =Before!$E$6 -> 0 | H3: =Before!$E$5 -> 0 | I3: =Before!$E$4 -> 0 | J3: =Before!G$5 -> doh | K3: TB cascade | L3: Under 5yrs | M3: =Before!B12 -> Headcount | N3: =Before!C12 -> 0 | O3: =Before!E12 -> 0 | P3: =Before!I12 -> 0 | Q3: =Before!M12 -> 0
B4: =Before!E$3 -> Monthly DQA | C4: =Before!G$3 -> DS-TB | D4: =Before!C$3 -> Before | E4: =Before!$C$4 -> Zolile Nonzapa | F4: =Before!$C$5 -> 0 | G4: =Before!$E$6 -> 0 | H4: =Before!$E$5 -> 0 | I4: =Before!$E$4 -> 0 | J4: =Before!G$5 -> doh | K4: TB cascade | L4: Under 5yrs | M4: =Before!B13 -> TB screening | N4: =Before!C13 -> 330 | O4: =Before!E13 -> 330 | P4: =Before!I13 -> 0 | Q4: =Before!M13 -> 0
B5: =Before!E$3 -> Monthly DQA | C5: =Before!G$3 -> DS-TB | D5: =Before!C$3 -> Before | E5: =Before!$C$4 -> Zolile Nonzapa | F5: =Before!$C$5 -> 0 | G5: =Before!$E$6 -> 0 | H5: =Before!$E$5 -> 0 | I5: =Before!$E$4 -> 0 | J5: =Before!G$5 -> doh | K5: TB cascade | L5: Under 5yrs | M5: =Before!B15 -> Client eligible for TB test | N5: =Before!C15 -> 0 | O5: =Before!E15 -> 0 | P5: =Before!I15 -> 0 | Q5: =Before!M15 -> 0
B6: =Before!E$3 -> Monthly DQA | C6: =Before!G$3 -> DS-TB | D6: =Before!C$3 -> Before | E6: =Before!$C$4 -> Zolile Nonzapa | F6: =Before!$C$5 -> 0 | G6: =Before!$E$6 -> 0 | H6: =Before!$E$5 -> 0 | I6: =Before!$E$4 -> 0 | J6: =Before!G$5 -> doh | K6: TB cascade | L6: Under 5yrs | M6: =Before!B17 -> TB test using GeneXpert | N6: =Before!C17 -> 0 | O6: =Before!E17 -> 0 | P6: =Before!I17 -> 0 | Q6: =Before!M17 -> 0
B7: =Before!E$3 -> Monthly DQA | C7: =Before!G$3 -> DS-TB | D7: =Before!C$3 -> Before | E7: =Before!$C$4 -> Zolile Nonzapa | F7: =Before!$C$5 -> 0 | G7: =Before!$E$6 -> 0 | H7: =Before!$E$5 -> 0 | I7: =Before!$E$4 -> 0 | J7: =Before!G$5 -> doh | K7: TB cascade | L7: Under 5yrs | M7: =Before!B18 -> DS-TB clinically diagnosed | N7: =Before!C18 -> 0 | O7: =Before!E18 -> 0 | P7: =Before!I18 -> 0 | Q7: =Before!M18 -> 0
B8: =Before!E$3 -> Monthly DQA | C8: =Before!G$3 -> DS-TB | D8: =Before!C$3 -> Before | E8: =Before!$C$4 -> Zolile Nonzapa | F8: =Before!$C$5 -> 0 | G8: =Before!$E$6 -> 0 | H8: =Before!$E$5 -> 0 | I8: =Before!$E$4 -> 0 | J8: =Before!G$5 -> doh | K8: TB cascade | L8: Under 5yrs | M8: =Before!B19 -> DS-TB Bacteriologically confirmed | N8: =Before!C19 -> 0 | O8: =Before!E19 -> 0 | P8: =Before!I19 -> 0 | Q8: =Before!M19 -> 0
B9: =Before!E$3 -> Monthly DQA | C9: =Before!G$3 -> DS-TB | D9: =Before!C$3 -> Before | E9: =Before!$C$4 -> Zolile Nonzapa | F9: =Before!$C$5 -> 0 | G9: =Before!$E$6 -> 0 | H9: =Before!$E$5 -> 0 | I9: =Before!$E$4 -> 0 | J9: =Before!G$5 -> doh | K9: TB cascade | L9: Under 5yrs | M9: =Before!B20 -> RR-TB bacteriologically confirmed | N9: =Before!C20 -> 0 | O9: =Before!E20 -> 0 | P9: =Before!I20 -> 0 | Q9: =Before!M20 -> 0
B10: =Before!E$3 -> Monthly DQA | C10: =Before!G$3 -> DS-TB | D10: =Before!C$3 -> Before | E10: =Before!$C$4 -> Zolile Nonzapa | F10: =Before!$C$5 -> 0 | G10: =Before!$E$6 -> 0 | H10: =Before!$E$5 -> 0 | I10: =Before!$E$4 -> 0 | J10: =Before!G$5 -> doh | K10: TB cascade | L10: Under 5yrs | M10: =Before!B22 -> DSTB treatment start | N10: =Before!C22 -> 0 | O10: =Before!E22 -> 0 | P10: =Before!I22 -> 1 | Q10: =Before!M22 -> 0
B11: =Before!E$3 -> Monthly DQA | C11: =Before!G$3 -> DS-TB | D11: =Before!C$3 -> Before | E11: =Before!$C$4 -> Zolile Nonzapa | F11: =Before!$C$5 -> 0 | G11: =Before!$E$6 -> 0 | H11: =Before!$E$5 -> 0 | I11: =Before!$E$4 -> 0 | J11: =Before!G$5 -> doh | K11: TB cascade | L11: Under 5yrs | M11: =Before!B24 -> Number initial lost to follow-up | N11: =Before!C24 -> 0 | O11: =Before!E24 -> 0 | P11: =Before!I24 -> -1 | Q11: =Before!M24 -> 0
B12: =Before!E$3 -> Monthly DQA | C12: =Before!G$3 -> DS-TB | D12: =Before!C$3 -> Before | E12: =Before!$C$4 -> Zolile Nonzapa | F12: =Before!$C$5 -> 0 | G12: =Before!$E$6 -> 0 | H12: =Before!$E$5 -> 0 | I12: =Before!$E$4 -> 0 | J12: =Before!G$5 -> doh | K12: TB cascade | L12: Under 5yrs | M12: =Before!B27 -> NHLS ALERTS DS-TB | N12: =Before!C27 -> 0 | O12: =Before!E27 -> 0 | P12: =Before!I27 -> 0 | Q12: =Before!M27 -> 0
B13: =Before!E$3 -> Monthly DQA | C13: =Before!G$3 -> DS-TB | D13: =Before!C$3 -> Before | E13: =Before!$C$4 -> Zolile Nonzapa | F13: =Before!$C$5 -> 0 | G13: =Before!$E$6 -> 0 | H13: =Before!$E$5 -> 0 | I13: =Before!$E$4 -> 0 | J13: =Before!G$5 -> doh | K13: TPT | L13: Under 5yrs | M13: =Before!B32 -> TB contact | N13: =Before!C32 -> 0 | O13: =Before!E32 -> 0 | P13: =Before!I32 -> 0 | Q13: =Before!M32 -> 0
B14: =Before!E$3 -> Monthly DQA | C14: =Before!G$3 -> DS-TB | D14: =Before!C$3 -> Before | E14: =Before!$C$4 -> Zolile Nonzapa | F14: =Before!$C$5 -> 0 | G14: =Before!$E$6 -> 0 | H14: =Before!$E$5 -> 0 | I14: =Before!$E$4 -> 0 | J14: =Before!G$5 -> doh | K14: TPT | L14: Under 5yrs | M14: =Before!B33 -> TB contact start on TPT | N14: =Before!C33 -> 0 | O14: =Before!E33 -> 0 | P14: =Before!I33 -> 0 | Q14: =Before!M33 -> 0
B15: =Before!E$3 -> Monthly DQA | C15: =Before!G$3 -> DS-TB | D15: =Before!C$3 -> Before | E15: =Before!$C$4 -> Zolile Nonzapa | F15: =Before!$C$5 -> 0 | G15: =Before!$E$6 -> 0 | H15: =Before!$E$5 -> 0 | I15: =Before!$E$4 -> 0 | J15: =Before!G$5 -> doh | K15: TPT | L15: All ages | M15: =Before!B36 -> PLWHIV on ART eligible for TPT | N15: =Before!D36 -> 0 | O15: =Before!F36 -> 0 | P15: =Before!J36 -> 0 | Q15: =Before!N36 -> 0
B16: =Before!E$3 -> Monthly DQA | C16: =Before!G$3 -> DS-TB | D16: =Before!C$3 -> Before | E16: =Before!$C$4 -> Zolile Nonzapa | F16: =Before!$C$5 -> 0 | G16: =Before!$E$6 -> 0 | H16: =Before!$E$5 -> 0 | I16: =Before!$E$4 -> 0 | J16: =Before!G$5 -> doh | K16: TPT | L16: All ages | M16: =Before!B37 -> PLWHIV on ART started TPT | N16: =Before!D37 -> 0 | O16: =Before!F37 -> 0 | P16: =Before!J37 -> 0 | Q16: =Before!N37 -> 0
B17: =Before!E$3 -> Monthly DQA | C17: =Before!G$3 -> DS-TB | D17: =Before!C$3 -> Before | E17: =Before!$C$4 -> Zolile Nonzapa | F17: =Before!$C$5 -> 0 | G17: =Before!$E$6 -> 0 | H17: =Before!$E$5 -> 0 | I17: =Before!$E$4 -> 0 | J17: =Before!G$5 -> doh | K17: DSTB outcome | L17: All ages | M17: =Before!B57 -> DSTB Treatment success | N17: =Before!C57 -> 65 | O17: =Before!D57 -> 65
B18: =Before!E$3 -> Monthly DQA | C18: =Before!G$3 -> DS-TB | D18: =Before!C$3 -> Before | E18: =Before!$C$4 -> Zolile Nonzapa | F18: =Before!$C$5 -> 0 | G18: =Before!$E$6 -> 0 | H18: =Before!$E$5 -> 0 | I18: =Before!$E$4 -> 0 | J18: =Before!G$5 -> doh | K18: DSTB outcome | L18: All ages | M18: =Before!B59 -> DSTB LTFU | N18: =Before!C59 -> 18 | O18: =Before!D59 -> 18
B19: =Before!E$3 -> Monthly DQA | C19: =Before!G$3 -> DS-TB | D19: =Before!C$3 -> Before | E19: =Before!$C$4 -> Zolile Nonzapa | F19: =Before!$C$5 -> 0 | G19: =Before!$E$6 -> 0 | H19: =Before!$E$5 -> 0 | I19: =Before!$E$4 -> 0 | J19: =Before!G$5 -> doh | K19: DSTB outcome | L19: All ages | M19: =Before!B61 -> DSTB Treatment Failure | N19: =Before!C61 -> 1 | O19: =Before!D61 -> 1
B20: =Before!E$3 -> Monthly DQA | C20: =Before!G$3 -> DS-TB | D20: =Before!C$3 -> Before | E20: =Before!$C$4 -> Zolile Nonzapa | F20: =Before!$C$5 -> 0 | G20: =Before!$E$6 -> 0 | H20: =Before!$E$5 -> 0 | I20: =Before!$E$4 -> 0 | J20: =Before!G$5 -> doh | K20: DSTB outcome | L20: All ages | M20: =Before!B63 -> DSTB Died | N20: =Before!C63 -> 4 | O20: =Before!D63 -> 4
B21: =Before!E$3 -> Monthly DQA | C21: =Before!G$3 -> DS-TB | D21: =Before!C$3 -> Before | E21: =Before!$C$4 -> Zolile Nonzapa | F21: =Before!$C$5 -> 0 | G21: =Before!$E$6 -> 0 | H21: =Before!$E$5 -> 0 | I21: =Before!$E$4 -> 0 | J21: =Before!G$5 -> doh | K21: DSTB outcome | L21: All ages | M21: =Before!B65 -> Not evaluated | N21: =Before!C65 -> 0 | O21: =Before!D65 -> 0
B22: =Before!E$3 -> Monthly DQA | C22: =Before!G$3 -> DS-TB | D22: =Before!C$3 -> Before | E22: =Before!$C$4 -> Zolile Nonzapa | F22: =Before!$C$5 -> 0 | G22: =Before!$E$6 -> 0 | H22: =Before!$E$5 -> 0 | I22: =Before!$E$4 -> 0 | J22: =Before!G$5 -> doh | K22: DSTB outcome | L22: All ages | M22: =Before!B67 -> DSTB Total | N22: =Before!C67 -> 88 | O22: =Before!D67 -> 88
B23: =Before!E$3 -> Monthly DQA | C23: =Before!G$3 -> DS-TB | D23: =Before!C$3 -> Before | E23: =Before!$C$4 -> Zolile Nonzapa | F23: =Before!$C$5 -> 0 | G23: =Before!$E$6 -> 0 | H23: =Before!$E$5 -> 0 | I23: =Before!$E$4 -> 0 | J23: =Before!G$5 -> doh | K23: DSTB outcome | L23: All ages | M23: =Before!B68 -> DSTB Transfer out (TFO) | N23: =Before!C68 -> 2 | O23: =Before!D68 -> 2
B24: =Before!E$3 -> Monthly DQA | C24: =Before!G$3 -> DS-TB | D24: =Before!C$3 -> Before | E24: =Before!$C$4 -> Zolile Nonzapa | F24: =Before!$C$5 -> 0 | G24: =Before!$E$6 -> 0 | H24: =Before!$E$5 -> 0 | I24: =Before!$E$4 -> 0 | J24: =Before!G$5 -> doh | K24: DSTB outcome | L24: All ages | M24: =Before!B70 -> TB Rif resistant | N24: =Before!C70 -> 0 | O24: =Before!D70 -> 0
